[2025-05-21 09:49:46,418] ERROR Detected path traversal attempt in '/1.png'
Traceback (most recent call last):
  File "/home/dvwuutxc/virtualenv/project/3.11/lib/python3.11/site-packages/django/core/handlers/exception.py", line 55, in inner
    response = get_response(request)
               ^^^^^^^^^^^^^^^^^^^^^
  File "/home/dvwuutxc/virtualenv/project/3.11/lib/python3.11/site-packages/django/core/handlers/base.py", line 197, in _get_response
    response = wrapped_callback(request, *callback_args, **callback_kwargs)
               ^^^^^^^^^^^^^^^^^^^^^^^^^^^^^^^^^^^^^^^^^^^^^^^^^^^^^^^^^^^^
  File "/home/dvwuutxc/virtualenv/project/3.11/lib/python3.11/site-packages/django/contrib/admin/options.py", line 719, in wrapper
    return self.admin_site.admin_view(view)(*args, **kwargs)
           ^^^^^^^^^^^^^^^^^^^^^^^^^^^^^^^^^^^^^^^^^^^^^^^^^
  File "/home/dvwuutxc/virtualenv/project/3.11/lib/python3.11/site-packages/django/utils/decorators.py", line 192, in _view_wrapper
    result = _process_exception(request, e)
             ^^^^^^^^^^^^^^^^^^^^^^^^^^^^^^
  File "/home/dvwuutxc/virtualenv/project/3.11/lib/python3.11/site-packages/django/utils/decorators.py", line 190, in _view_wrapper
    response = view_func(request, *args, **kwargs)
               ^^^^^^^^^^^^^^^^^^^^^^^^^^^^^^^^^^^
  File "/home/dvwuutxc/virtualenv/project/3.11/lib/python3.11/site-packages/django/views/decorators/cache.py", line 80, in _view_wrapper
    response = view_func(request, *args, **kwargs)
               ^^^^^^^^^^^^^^^^^^^^^^^^^^^^^^^^^^^
  File "/home/dvwuutxc/virtualenv/project/3.11/lib/python3.11/site-packages/django/contrib/admin/sites.py", line 246, in inner
    return view(request, *args, **kwargs)
           ^^^^^^^^^^^^^^^^^^^^^^^^^^^^^^
  File "/home/dvwuutxc/virtualenv/project/3.11/lib/python3.11/site-packages/django/contrib/admin/options.py", line 1987, in change_view
    return self.changeform_view(request, object_id, form_url, extra_context)
           ^^^^^^^^^^^^^^^^^^^^^^^^^^^^^^^^^^^^^^^^^^^^^^^^^^^^^^^^^^^^^^^^^
  File "/home/dvwuutxc/virtualenv/project/3.11/lib/python3.11/site-packages/django/utils/decorators.py", line 48, in _wrapper
    return bound_method(*args, **kwargs)
           ^^^^^^^^^^^^^^^^^^^^^^^^^^^^^
  File "/home/dvwuutxc/virtualenv/project/3.11/lib/python3.11/site-packages/django/utils/decorators.py", line 192, in _view_wrapper
    result = _process_exception(request, e)
             ^^^^^^^^^^^^^^^^^^^^^^^^^^^^^^
  File "/home/dvwuutxc/virtualenv/project/3.11/lib/python3.11/site-packages/django/utils/decorators.py", line 190, in _view_wrapper
    response = view_func(request, *args, **kwargs)
               ^^^^^^^^^^^^^^^^^^^^^^^^^^^^^^^^^^^
  File "/home/dvwuutxc/virtualenv/project/3.11/lib/python3.11/site-packages/django/contrib/admin/options.py", line 1843, in changeform_view
    return self._changeform_view(request, object_id, form_url, extra_context)
           ^^^^^^^^^^^^^^^^^^^^^^^^^^^^^^^^^^^^^^^^^^^^^^^^^^^^^^^^^^^^^^^^^^
  File "/home/dvwuutxc/virtualenv/project/3.11/lib/python3.11/site-packages/django/contrib/admin/options.py", line 1894, in _changeform_view
    self.save_model(request, new_object, form, not add)
  File "/home/dvwuutxc/project/fashion/admin.py", line 13, in save_model
    super().save_model(request, obj, form, change)
  File "/home/dvwuutxc/virtualenv/project/3.11/lib/python3.11/site-packages/django/contrib/admin/options.py", line 1314, in save_model
    obj.save()
  File "/home/dvwuutxc/project/fashion/models.py", line 34, in save
    super().save(*args, **kwargs)
  File "/home/dvwuutxc/virtualenv/project/3.11/lib/python3.11/site-packages/django/db/models/base.py", line 902, in save
    self.save_base(
  File "/home/dvwuutxc/virtualenv/project/3.11/lib/python3.11/site-packages/django/db/models/base.py", line 1008, in save_base
    updated = self._save_table(
              ^^^^^^^^^^^^^^^^^
  File "/home/dvwuutxc/virtualenv/project/3.11/lib/python3.11/site-packages/django/db/models/base.py", line 1128, in _save_table
    values = [
             ^
  File "/home/dvwuutxc/virtualenv/project/3.11/lib/python3.11/site-packages/django/db/models/base.py", line 1132, in <listcomp>
    (getattr(self, f.attname) if raw else f.pre_save(self, False)),
                                          ^^^^^^^^^^^^^^^^^^^^^^^
  File "/home/dvwuutxc/virtualenv/project/3.11/lib/python3.11/site-packages/django/db/models/fields/files.py", line 338, in pre_save
    file.save(file.name, file.file, save=False)
  File "/home/dvwuutxc/virtualenv/project/3.11/lib/python3.11/site-packages/django/db/models/fields/files.py", line 98, in save
    name = self.field.generate_filename(self.instance, name)
           ^^^^^^^^^^^^^^^^^^^^^^^^^^^^^^^^^^^^^^^^^^^^^^^^^
  File "/home/dvwuutxc/virtualenv/project/3.11/lib/python3.11/site-packages/django/db/models/fields/files.py", line 357, in generate_filename
    filename = validate_file_name(filename, allow_relative_path=True)
               ^^^^^^^^^^^^^^^^^^^^^^^^^^^^^^^^^^^^^^^^^^^^^^^^^^^^^^
  File "/home/dvwuutxc/virtualenv/project/3.11/lib/python3.11/site-packages/django/core/files/utils.py", line 17, in validate_file_name
    raise SuspiciousFileOperation(
django.core.exceptions.SuspiciousFileOperation: Detected path traversal attempt in '/1.png'
